INFO:tornado.access: 200 GET / (127.0.0.1) 1.32ms (2015-12-17 12:28:20; web.py:1946)
WARNING:tornado.access: 404 GET /favicon.ico (127.0.0.1) 3.87ms (2015-12-17 12:28:20; web.py:1946)
WARNING:root: Caught signal: 2 (2015-12-17 12:41:48; app.py:24)
INFO:root: Stopping http server (2015-12-17 12:41:48; app.py:29)
ERROR:tornado.application: Exception in callback <functools.partial object at 0x105e80260> (2015-12-17 12:41:48; ioloop.py:629)
Traceback (most recent call last):
  File "/Users/dinghailong/Git/github/z-fork/hunter/venv/lib/python2.7/site-packages/tornado/ioloop.py", line 600, in _run_callback
    ret = callback()
  File "/Users/dinghailong/Git/github/z-fork/hunter/venv/lib/python2.7/site-packages/tornado/stack_context.py", line 275, in null_wrapper
    return fn(*args, **kwargs)
  File "/Users/dinghailong/Git/github/z-fork/hunter/hunter/app.py", line 32, in shutdown
    logging.info('Will shutdown in %s seconds ...', settings.MAX_WAIT_SECONDS_BEFORE_SHUTDOWN)
AttributeError: 'dict' object has no attribute 'MAX_WAIT_SECONDS_BEFORE_SHUTDOWN'
WARNING:root: Caught signal: 2 (2015-12-17 12:42:03; app.py:24)
INFO:root: Stopping http server (2015-12-17 12:42:03; app.py:29)
ERROR:tornado.application: Exception in callback <functools.partial object at 0x10c562260> (2015-12-17 12:42:03; ioloop.py:629)
Traceback (most recent call last):
  File "/Users/dinghailong/Git/github/z-fork/hunter/venv/lib/python2.7/site-packages/tornado/ioloop.py", line 600, in _run_callback
    ret = callback()
  File "/Users/dinghailong/Git/github/z-fork/hunter/venv/lib/python2.7/site-packages/tornado/stack_context.py", line 275, in null_wrapper
    return fn(*args, **kwargs)
  File "/Users/dinghailong/Git/github/z-fork/hunter/hunter/app.py", line 32, in shutdown
    logging.info('Will shutdown in %s seconds ...', settings.MAX_WAIT_SECONDS_BEFORE_SHUTDOWN)
AttributeError: 'dict' object has no attribute 'MAX_WAIT_SECONDS_BEFORE_SHUTDOWN'
WARNING:root: Caught signal: 2 (2015-12-17 12:43:45; app.py:24)
INFO:root: Stopping http server (2015-12-17 12:43:45; app.py:29)
ERROR:tornado.application: Exception in callback <functools.partial object at 0x110110260> (2015-12-17 12:43:45; ioloop.py:629)
Traceback (most recent call last):
  File "/Users/dinghailong/Git/github/z-fork/hunter/venv/lib/python2.7/site-packages/tornado/ioloop.py", line 600, in _run_callback
    ret = callback()
  File "/Users/dinghailong/Git/github/z-fork/hunter/venv/lib/python2.7/site-packages/tornado/stack_context.py", line 275, in null_wrapper
    return fn(*args, **kwargs)
  File "/Users/dinghailong/Git/github/z-fork/hunter/hunter/app.py", line 32, in shutdown
    logging.info('Will shutdown in %s seconds ...', settings.MAX_WAIT_SECONDS_BEFORE_SHUTDOWN)
AttributeError: 'dict' object has no attribute 'MAX_WAIT_SECONDS_BEFORE_SHUTDOWN'
WARNING:root: Caught signal: 2 (2015-12-17 12:44:43; app.py:24)
INFO:root: Stopping http server (2015-12-17 12:44:43; app.py:29)
INFO:root: Will shutdown in 10 seconds ... (2015-12-17 12:44:43; app.py:32)
INFO:root: Shutdown (2015-12-17 12:44:43; app.py:42)
